Workbook

Sheet README
A1: Spread synthetic roguelite item test data
A3: Generated rows | B3: 5000 | D3: Rarity | E3: Count
A4: Main table | B4: Items!A1:AN5001 | D4: Common | E4: =COUNTIF(Items!$D$2:$D$5001,D4) -> 2179
A5: Fixture sheet | B5: CellTypeFixtures | D5: Uncommon | E5: =COUNTIF(Items!$D$2:$D$5001,D5) -> 1244
A6: Rarity values | B6: Common, Uncommon, Rare, Epic, Legendary, Cursed, Relic | D6: Rare | E6: =COUNTIF(Items!$D$2:$D$5001,D6) -> 750
A7: Contains booleans | B7: TRUE/FALSE columns F and R:V; formula boolean in AN | D7: Epic | E7: =COUNTIF(Items!$D$2:$D$5001,D7) -> 434
A8: Contains formulas | B8: AD:AJ and AN in Items; B9:B16 in CellTypeFixtures | D8: Legendary | E8: =COUNTIF(Items!$D$2:$D$5001,D8) -> 184
A9: Contains string formulas | B9: AH and AJ in Items; B10 in CellTypeFixtures | D9: Cursed | E9: =COUNTIF(Items!$D$2:$D$5001,D9) -> 163
A10: Contains merged cells | B10: README!A1:H1 and CellTypeFixtures!A1:H1/A3:B3 | D10: Relic | E10: =COUNTIF(Items!$D$2:$D$5001,D10) -> 46
A11: Contains XML fixtures | B11: shared formula, shared string, inline string
A12: Seed | B12: 20260703

Sheet Items
A1: id | B1: item_name | C1: item_description | D1: rarity | E1: price | F1: applies_to_character | G1: icon_index | H1: damage_modifier | I1: hp_modifier | J1: projectile_size_modifier | K1: range_modifier | L1: shot_speed_modifier | M1: player_speed_modifier | N1: luck_modifier | O1: knockback_modifier | P1: minimum_level | Q1: maximum_level | R1: is_breakable | S1: is_poisonable | T1: can_explode | U1: is_freezable | V1: is_movable | W1: element_affinity | X1: item_category | Y1: spawn_pool | Z1: weight | AA1: synergy_tags | AB1: script_hook | AC1: internal_note | AD1: tier_score | AE1: computed_price | AF1: level_span | AG1: description_length | AH1: loot_bucket | AI1: has_negative_modifier | AJ1: tuning_warning | AK1: literal_formula_like_text | AL1: optional_upgrade_id | AM1: last_tuned_at | AN1: min_max_valid
A2: itm_00001 | B2: Cracked Rocket of the Glass Moon | C2: A uncommon active that nudges coins only when the room is clear. Generated test item #0001; element=Rust; pool=Shop. | D2: Uncommon | E2: 33 | F2: FALSE | G2: 1269 | H2: 0 | I2: 0 | J2: 0.17 | K2: 0 | L2: 0 | M2: 0.17 | N2: 0 | O2: 0 | P2: 4 | Q2: 8 | R2: FALSE | S2: FALSE | T2: FALSE | U2: FALSE | V2: TRUE | W2: Rust | X2: Active | Y2: Shop | Z2: 2.865 | AA2: rust | AB2: scr_item_cracked_rocket_of_the_glass_moon | AC2: seed=20260703; class_filter=Witch; parser_note=row_1 | AD2: =ROUND(ABS(H2)*8+ABS(I2)*1.5+ABS(J2)*3+ABS(K2)*2+ABS(L2)*2+ABS(M2)*2+ABS(N2)*2+ABS(O2)*2+IF(D2="Legendary",10,IF(D2="Relic",12,IF(D2="Epic",7,IF(D2="Rare",4,IF(D2="Uncommon",2,IF(D2="Cursed",5,1)))))),2) -> 2.85 | AE2: =MAX(0,ROUND(E2*(1+AD2/25)+IF(R2,2,0)+IF(T2,4,0),0)) -> 37 | AF2: =Q2-P2+1 -> 5 | AG2: =LEN(C2) -> 116 | AH2: =IF(D2="Legendary","boss-vault",IF(D2="Relic","secret-room",IF(D2="Cursed","curse-room",IF(AD2>12,"rare-chest","standard")))) -> standard | AI2: =OR(H2<0,I2<0,J2<0,K2<0,L2<0,M2<0,N2<0,O2<0) -> FALSE | AJ2: =IF(AND(P2<=Q2,AE2>=0,AF2>0),IF(OR(AD2>18,AND(D2="Common",AD2>10),AND(D2="Legendary",AE2<80)),"review: balance outlier",IF(AND(R2,T2,U2),"review: volatile physics",IF(COUNTIF(AA2,"*fire*")+COUNTIF(AA2,"*poison*")+COUNTIF(AA2,"*ice*")>=2,"review: multi-status synergy","ok"))),"invalid: level/price") -> ok | AK2: =not_a_formula_0001 | AM2: 46168 | AN2: =P2<=Q2 -> TRUE
A3: itm_00002 | B3: Static Anchor of Soft Explosions | C3: A uncommon weaponmod that amplifies doors if the player keeps moving. Generated test item #0002; element=Ice; pool=Shop. | D3: Uncommon | E3: 29 | F3: FALSE | G3: 1331 | H3: 0 | I3: 1 | J3: 0 | K3: 0 | L3: 0 | M3: 0 | N3: 2.12 | O3: 0 | P3: 7 | Q3: 9 | R3: FALSE | S3: TRUE | T3: FALSE | U3: FALSE | V3: TRUE | W3: Ice | X3: WeaponMod | Y3: Shop | Z3: 1.561 | AA3: ice,poisonable | AB3: scr_item_static_anchor_of_soft_explosions | AC3: seed=20260703; class_filter=Monk; parser_note=row_2 | AD3: =ROUND(ABS(H3)*8+ABS(I3)*1.5+ABS(J3)*3+ABS(K3)*2+ABS(L3)*2+ABS(M3)*2+ABS(N3)*2+ABS(O3)*2+IF(D3="Legendary",10,IF(D3="Relic",12,IF(D3="Epic",7,IF(D3="Rare",4,IF(D3="Uncommon",2,IF(D3="Cursed",5,1)))))),2) -> 7.74 | AE3: =MAX(0,ROUND(E3*(1+AD3/25)+IF(R3,2,0)+IF(T3,4,0),0)) -> 38 | AF3: =Q3-P3+1 -> 3 | AG3: =LEN(C3) -> 120 | AH3: =IF(D3="Legendary","boss-vault",IF(D3="Relic","secret-room",IF(D3="Cursed","curse-room",IF(AD3>12,"rare-chest","standard")))) -> standard | AI3: =OR(H3<0,I3<0,J3<0,K3<0,L3<0,M3<0,N3<0,O3<0) -> FALSE | AJ3: =IF(AND(P3<=Q3,AE3>=0,AF3>0),IF(OR(AD3>18,AND(D3="Common",AD3>10),AND(D3="Legendary",AE3<80)),"review: balance outlier",IF(AND(R3,T3,U3),"review: volatile physics",IF(COUNTIF(AA3,"*fire*")+COUNTIF(AA3,"*poison*")+COUNTIF(AA3,"*ice*")>=2,"review: multi-status synergy","ok"))),"invalid: level/price") -> review: multi-status synergy | AK3: =not_a_formula_0002 | AM3: 46027 | AN3: =P3<=Q3 -> TRUE
A4: itm_00003 | B4: Glass Candle of the Basement | C4: A common consumable that spoils doors while lowering control. Generated test item #0003; element=None; pool=Treasure. | D4: Common | E4: 18 | F4: TRUE | G4: 1161 | H4: 0 | I4: 0 | J4: 0 | K4: 0 | L4: 0 | M4: 0.21 | N4: 2.48 | O4: -0.16 | P4: 3 | Q4: 5 | R4: TRUE | S4: TRUE | T4: FALSE | U4: TRUE | V4: TRUE | W4: None | X4: Consumable | Y4: Treasure | Z4: 1.527 | AA4: poisonable | AB4: scr_item_glass_candle_of_the_basement | AC4: seed=20260703; class_filter=Alchemist; parser_note=row_3 | AD4: =ROUND(ABS(H4)*8+ABS(I4)*1.5+ABS(J4)*3+ABS(K4)*2+ABS(L4)*2+ABS(M4)*2+ABS(N4)*2+ABS(O4)*2+IF(D4="Legendary",10,IF(D4="Relic",12,IF(D4="Epic",7,IF(D4="Rare",4,IF(D4="Uncommon",2,IF(D4="Cursed",5,1)))))),2) -> 6.7 | AE4: =MAX(0,ROUND(E4*(1+AD4/25)+IF(R4,2,0)+IF(T4,4,0),0)) -> 25 | AF4: =Q4-P4+1 -> 3 | AG4: =LEN(C4) -> 117 | AH4: =IF(D4="Legendary","boss-vault",IF(D4="Relic","secret-room",IF(D4="Cursed","curse-room",IF(AD4>12,"rare-chest","standard")))) -> standard | AI4: =OR(H4<0,I4<0,J4<0,K4<0,L4<0,M4<0,N4<0,O4<0) -> TRUE | AJ4: =IF(AND(P4<=Q4,AE4>=0,AF4>0),IF(OR(AD4>18,AND(D4="Common",AD4>10),AND(D4="Legendary",AE4<80)),"review: balance outlier",IF(AND(R4,T4,U4),"review: volatile physics",IF(COUNTIF(AA4,"*fire*")+COUNTIF(AA4,"*poison*")+COUNTIF(AA4,"*ice*")>=2,"review: multi-status synergy","ok"))),"invalid: level/price") -> ok | AK4: =not_a_formula_0003 | AM4: 46196 | AN4: =P4<=Q4 -> TRUE
A5: itm_00004 | B5: Damp Lantern of the Glass Moon | C5: A cursed passive that spoils coins while lowering control. Generated test item #0004; element=None; pool=Treasure. | D5: Cursed | E5: 48 | F5: TRUE | G5: 193 | H5: 0 | I5: -1 | J5: -0.1 | K5: 0.63 | L5: 0 | M5: 0.3 | N5: 0 | O5: 0.75 | P5: 2 | Q5: 7 | R5: TRUE | S5: TRUE | T5: FALSE | U5: FALSE | V5: FALSE | W5: None | X5: Passive | Y5: Treasure | Z5: 3.294 | AA5: poisonable,cursed | AB5: scr_item_damp_lantern_of_the_glass_moon | AC5: seed=20260703; class_filter=Any; parser_note=row_4 | AD5: =ROUND(ABS(H5)*8+ABS(I5)*1.5+ABS(J5)*3+ABS(K5)*2+ABS(L5)*2+ABS(M5)*2+ABS(N5)*2+ABS(O5)*2+IF(D5="Legendary",10,IF(D5="Relic",12,IF(D5="Epic",7,IF(D5="Rare",4,IF(D5="Uncommon",2,IF(D5="Cursed",5,1)))))),2) -> 10.16 | AE5: =MAX(0,ROUND(E5*(1+AD5/25)+IF(R5,2,0)+IF(T5,4,0),0)) -> 70 | AF5: =Q5-P5+1 -> 6 | AG5: =LEN(C5) -> 114 | AH5: =IF(D5="Legendary","boss-vault",IF(D5="Relic","secret-room",IF(D5="Cursed","curse-room",IF(AD5>12,"rare-chest","standard")))) -> curse-room | AI5: =OR(H5<0,I5<0,J5<0,K5<0,L5<0,M5<0,N5<0,O5<0) -> TRUE | AJ5: =IF(AND(P5<=Q5,AE5>=0,AF5>0),IF(OR(AD5>18,AND(D5="Common",AD5>10),AND(D5="Legendary",AE5<80)),"review: balance outlier",IF(AND(R5,T5,U5),"review: volatile physics",IF(COUNTIF(AA5,"*fire*")+COUNTIF(AA5,"*poison*")+COUNTIF(AA5,"*ice*")>=2,"review: multi-status synergy","ok"))),"invalid: level/price") -> ok | AK5: =not_a_formula_0004 | AL5: upg_228 | AM5: 46062 | AN5: =P5<=Q5 -> TRUE
A6: itm_00005 | B6: Echoing Orb of Static | C6: A uncommon active that amplifies doors when luck disagrees. Generated test item #0005; element=Cosmic; pool=Treasure. | D6: Uncommon | E6: 29 | F6: TRUE | G6: 1430 | H6: 0 | I6: 1 | J6: 0.51 | K6: 0 | L6: 0 | M6: 0 | N6: 0 | O6: 0.97 | P6: 7 | Q6: 7 | R6: FALSE | S6: FALSE | T6: FALSE | U6: FALSE | V6: FALSE | W6: Cosmic | X6: Active | Y6: Treasure | Z6: 1.926 | AA6: cosmic | AB6: scr_item_echoing_orb_of_static | AC6: seed=20260703; class_filter=Witch; parser_note=row_5 | AD6: =ROUND(ABS(H6)*8+ABS(I6)*1.5+ABS(J6)*3+ABS(K6)*2+ABS(L6)*2+ABS(M6)*2+ABS(N6)*2+ABS(O6)*2+IF(D6="Legendary",10,IF(D6="Relic",12,IF(D6="Epic",7,IF(D6="Rare",4,IF(D6="Uncommon",2,IF(D6="Cursed",5,1)))))),2) -> 6.97 | AE6: =MAX(0,ROUND(E6*(1+AD6/25)+IF(R6,2,0)+IF(T6,4,0),0)) -> 37 | AF6: =Q6-P6+1 -> 1 | AG6: =LEN(C6) -> 117 | AH6: =IF(D6="Legendary","boss-vault",IF(D6="Relic","secret-room",IF(D6="Cursed","curse-room",IF(AD6>12,"rare-chest","standard")))) -> standard | AI6: =OR(H6<0,I6<0,J6<0,K6<0,L6<0,M6<0,N6<0,O6<0) -> FALSE | AJ6: =IF(AND(P6<=Q6,AE6>=0,AF6>0),IF(OR(AD6>18,AND(D6="Common",AD6>10),AND(D6="Legendary",AE6<80)),"review: balance outlier",IF(AND(R6,T6,U6),"review: volatile physics",IF(COUNTIF(AA6,"*fire*")+COUNTIF(AA6,"*poison*")+COUNTIF(AA6,"*ice*")>=2,"review: multi-status synergy","ok"))),"invalid: level/price") -> ok | AK6: =not_a_formula_0005 | AM6: 46179 | AN6: =P6<=Q6 -> TRUE
A7: itm_00006 | B7: Haunted Onion of Tiny Doom | C7: A uncommon active that duplicates hearts only when the room is clear. Generated test item #0006; element=Void; pool=Shop. | D7: Uncommon | E7: 23 | F7: TRUE | G7: 474 | H7: 0 | I7: 0 | J7: 0 | K7: 0.6 | L7: 0.01 | M7: 0.41 | N7: 0 | O7: 0 | P7: 9 | Q7: 10 | R7: FALSE | S7: FALSE | T7: FALSE | U7: TRUE | V7: TRUE | W7: Void | X7: Active | Y7: Shop | Z7: 1.54 | AA7: void | AB7: scr_item_haunted_onion_of_tiny_doom | AC7: seed=20260703; class_filter=Any; parser_note=row_6 | AD7: =ROUND(ABS(H7)*8+ABS(I7)*1.5+ABS(J7)*3+ABS(K7)*2+ABS(L7)*2+ABS(M7)*2+ABS(N7)*2+ABS(O7)*2+IF(D7="Legendary",10,IF(D7="Relic",12,IF(D7="Epic",7,IF(D7="Rare",4,IF(D7="Uncommon",2,IF(D7="Cursed",5,1)))))),2) -> 4.04 | AE7: =MAX(0,ROUND(E7*(1+AD7/25)+IF(R7,2,0)+IF(T7,4,0),0)) -> 27 | AF7: =Q7-P7+1 -> 2 | AG7: =LEN(C7) -> 121 | AH7: =IF(D7="Legendary","boss-vault",IF(D7="Relic","secret-room",IF(D7="Cursed","curse-room",IF(AD7>12,"rare-chest","standard")))) -> standard | AI7: =OR(H7<0,I7<0,J7<0,K7<0,L7<0,M7<0,N7<0,O7<0) -> FALSE | AJ7: =IF(AND(P7<=Q7,AE7>=0,AF7>0),IF(OR(AD7>18,AND(D7="Common",AD7>10),AND(D7="Legendary",AE7<80)),"review: balance outlier",IF(AND(R7,T7,U7),"review: volatile physics",IF(COUNTIF(AA7,"*fire*")+COUNTIF(AA7,"*poison*")+COUNTIF(AA7,"*ice*")>=2,"review: multi-status synergy","ok"))),"invalid: level/price") -> ok | AK7: =not_a_formula_0006 | AM7: 46051 | AN7: =P7<=Q7 -> TRUE
A8: itm_00007 | B8: Mossy Mask of Slippery Angles | C8: A common orbital that taxes hearts when luck disagrees. Generated test item #0007; element=Holy; pool=Library. | D8: Common | E8: 17 | F8: TRUE | G8: 1559 | H8: 0.69 | I8: 0 | J8: 0 | K8: 0.42 | L8: 0 | M8: 0 | N8: 0 | O8: 0 | P8: 7 | Q8: 8 | R8: FALSE | S8: FALSE | T8: FALSE | U8: TRUE | V8: TRUE | W8: Holy | X8: Orbital | Y8: Library | Z8: 3.46 | AA8: holy,companion | AB8: scr_item_mossy_mask_of_slippery_angles | AC8: seed=20260703; class_filter=Alchemist; parser_note=row_7 | AD8: =ROUND(ABS(H8)*8+ABS(I8)*1.5+ABS(J8)*3+ABS(K8)*2+ABS(L8)*2+ABS(M8)*2+ABS(N8)*2+ABS(O8)*2+IF(D8="Legendary",10,IF(D8="Relic",12,IF(D8="Epic",7,IF(D8="Rare",4,IF(D8="Uncommon",2,IF(D8="Cursed",5,1)))))),2) -> 7.36 | AE8: =MAX(0,ROUND(E8*(1+AD8/25)+IF(R8,2,0)+IF(T8,4,0),0)) -> 22 | AF8: =Q8-P8+1 -> 2 | AG8: =LEN(C8) -> 110 | AH8: =IF(D8="Legendary","boss-vault",IF(D8="Relic","secret-room",IF(D8="Cursed","curse-room",IF(AD8>12,"rare-chest","standard")))) -> standard | AI8: =OR(H8<0,I8<0,J8<0,K8<0,L8<0,M8<0,N8<0,O8<0) -> FALSE | AJ8: =IF(AND(P8<=Q8,AE8>=0,AF8>0),IF(OR(AD8>18,AND(D8="Common",AD8>10),AND(D8="Legendary",AE8<80)),"review: balance outlier",IF(AND(R8,T8,U8),"review: volatile physics",IF(COUNTIF(AA8,"*fire*")+COUNTIF(AA8,"*poison*")+COUNTIF(AA8,"*ice*")>=2,"review: multi-status synergy","ok"))),"invalid: level/price") -> ok | AK8: =not_a_formula_0007 | AL8: upg_034 | AM8: 46117 | AN8: =P8<=Q8 -> TRUE
A9: itm_00008 | B9: Feral Dice of Bad Ideas | C9: A cursed consumable that nudges bombs but attracts trouble. Generated test item #0008; element=Fire; pool=Treasure. | D9: Cursed | E9: 33 | F9: TRUE | G9: 104 | H9: 0 | I9: 0 | J9: 0 | K9: 0 | L9: 0 | M9: 0.28 | N9: 0 | O9: -0.34 | P9: 7 | Q9: 10 | R9: TRUE | S9: TRUE | T9: TRUE | U9: FALSE | V9: FALSE | W9: Fire | X9: Consumable | Y9: Treasure | Z9: 1.406 | AA9: fire,explosive,poisonable,cursed | AB9: scr_item_feral_dice_of_bad_ideas | AC9: seed=20260703; class_filter=Monk; parser_note=row_8 | AD9: =ROUND(ABS(H9)*8+ABS(I9)*1.5+ABS(J9)*3+ABS(K9)*2+ABS(L9)*2+ABS(M9)*2+ABS(N9)*2+ABS(O9)*2+IF(D9="Legendary",10,IF(D9="Relic",12,IF(D9="Epic",7,IF(D9="Rare",4,IF(D9="Uncommon",2,IF(D9="Cursed",5,1)))))),2) -> 6.24 | AE9: =MAX(0,ROUND(E9*(1+AD9/25)+IF(R9,2,0)+IF(T9,4,0),0)) -> 47 | AF9: =Q9-P9+1 -> 4 | AG9: =LEN(C9) -> 115 | AH9: =IF(D9="Legendary","boss-vault",IF(D9="Relic","secret-room",IF(D9="Cursed","curse-room",IF(AD9>12,"rare-chest","standard")))) -> curse-room | AI9: =OR(H9<0,I9<0,J9<0,K9<0,L9<0,M9<0,N9<0,O9<0) -> TRUE | AJ9: =IF(AND(P9<=Q9,AE9>=0,AF9>0),IF(OR(AD9>18,AND(D9="Common",AD9>10),AND(D9="Legendary",AE9<80)),"review: balance outlier",IF(AND(R9,T9,U9),"review: volatile physics",IF(COUNTIF(AA9,"*fire*")+COUNTIF(AA9,"*poison*")+COUNTIF(AA9,"*ice*")>=2,"review: multi-status synergy","ok"))),"invalid: level/price") -> review: multi-status synergy | AK9: =not_a_formula_0008 | AM9: 46131 | AN9: =P9<=Q9 -> TRUE
A10: itm_00009 | B10: Radiant Bell of Friendly Fire | C10: A rare weaponmod that reroutes reloads after every third hit. Generated test item #0009; element=None; pool=Cursed. | D10: Rare | E10: 54 | F10: TRUE | G10: 713 | H10: 0 | I10: 0 | J10: 0.17 | K10: 0 | L10: 0 | M10: -0.06 | N10: 0 | O10: 0.62 | P10: 9 | Q10: 9 | R10: FALSE | S10: FALSE | T10: FALSE | U10: TRUE | V10: FALSE | W10: None | X10: WeaponMod | Y10: Cursed | Z10: 2.109 | AA10: neutral | AB10: scr_item_radiant_bell_of_friendly_fire | AC10: seed=20260703; class_filter=Engineer; parser_note=row_9 | AD10: =ROUND(ABS(H10)*8+ABS(I10)*1.5+ABS(J10)*3+ABS(K10)*2+ABS(L10)*2+ABS(M10)*2+ABS(N10)*2+ABS(O10)*2+IF(D10="Legendary",10,IF(D10="Relic",12,IF(D10="Epic",7,IF(D10="Rare",4,IF(D10="Uncommon",2,IF(D10="Cursed",5,1)))))),2) -> 5.87 | AE10: =MAX(0,ROUND(E10*(1+AD10/25)+IF(R10,2,0)+IF(T10,4,0),0)) -> 67 | AF10: =Q10-P10+1 -> 1 | AG10: =LEN(C10) -> 115 | AH10: =IF(D10="Legendary","boss-vault",IF(D10="Relic","secret-room",IF(D10="Cursed","curse-room",IF(AD10>12,"rare-chest","standard")))) -> standard | AI10: =OR(H10<0,I10<0,J10<0,K10<0,L10<0,M10<0,N10<0,O10<0) -> TRUE | AJ10: =IF(AND(P10<=Q10,AE10>=0,AF10>0),IF(OR(AD10>18,AND(D10="Common",AD10>10),AND(D10="Legendary",AE10<80)),"review: balance outlier",IF(AND(R10,T10,U10),"review: volatile physics",IF(COUNTIF(AA10,"*fire*")+COUNTIF(AA10,"*poison*")+COUNTIF(AA10,"*ice*")>=2,"review: multi-status synergy","ok"))),"invalid: level/price") -> ok | AK10: =not_a_formula_0009 | AM10: 46123 | AN10: =P10<=Q10 -> TRUE
A11: itm_00010 | B11: Patchwork Slingshot of Tuesday | C11: A uncommon charm that taxes bullets but attracts trouble. Generated test item #0010; element=Lightning; pool=Secret. | D11: Uncommon | E11: 20 | F11: TRUE | G11: 1058 | H11: 0.9 | I11: 0 | J11: 0 | K11: 0.1 | L11: 0.45 | M11: 0 | N11: 1.66 | O11: 0 | P11: 3 | Q11: 3 | R11: TRUE | S11: TRUE | T11: TRUE | U11: TRUE | V11: TRUE | W11: Lightning | X11: Charm | Y11: Secret | Z11: 2.838 | AA11: lightning,explosive,poisonable | AB11: scr_item_patchwork_slingshot_of_tuesday | AC11: seed=20260703; class_filter=Brawler; parser_note=row_10 | AD11: =ROUND(ABS(H11)*8+ABS(I11)*1.5+ABS(J11)*3+ABS(K11)*2+ABS(L11)*2+ABS(M11)*2+ABS(N11)*2+ABS(O11)*2+IF(D11="Legendary",10,IF(D11="Relic",12,IF(D11="Epic",7,IF(D11="Rare",4,IF(D11="Uncommon",2,IF(D11="Cursed",5,1)))))),2) -> 13.62 | AE11: =MAX(0,ROUND(E11*(1+AD11/25)+IF(R11,2,0)+IF(T11,4,0),0)) -> 37 | AF11: =Q11-P11+1 -> 1 | AG11: =LEN(C11) -> 116 | AH11: =IF(D11="Legendary","boss-vault",IF(D11="Relic","secret-room",IF(D11="Cursed","curse-room",IF(AD11>12,"rare-chest","standard")))) -> rare-chest | AI11: =OR(H11<0,I11<0,J11<0,K11<0,L11<0,M11<0,N11<0,O11<0) -> FALSE | AJ11: =IF(AND(P11<=Q11,AE11>=0,AF11>0),IF(OR(AD11>18,AND(D11="Common",AD11>10),AND(D11="Legendary",AE11<80)),"review: balance outlier",IF(AND(R11,T11,U11),"review: volatile physics",IF(COUNTIF(AA11,"*fire*")+COUNTIF(AA11,"*poison*")+COUNTIF(AA11,"*ice*")>=2,"review: multi-status synergy","ok"))),"invalid: level/price") -> review: volatile physics | AK11: =not_a_formula_0010 | AL11: upg_331 | AM11: 46062 | AN11: =P11<=Q11 -> TRUE
A12: itm_00011 | B12: Caffeinated Mirror of the Basement | C12: A uncommon weaponmod that duplicates dodges if the player keeps moving. Generated test item #0011; element=Poison; pool=Arcade. | D12: Uncommon | E12: 23 | F12: TRUE | G12: 1855 | H12: -0.01 | I12: 1 | J12: 0 | K12: 0 | L12: 0 | M12: 0 | N12: 0 | O12: 0 | P12: 7 | Q12: 10 | R12: FALSE | S12: FALSE | T12: FALSE | U12: TRUE | V12: TRUE | W12: Poison | X12: WeaponMod | Y12: Arcade | Z12: 0.699 | AA12: poison | AB12: scr_item_caffeinated_mirror_of_the_basement | AC12: seed=20260703; class_filter=Gunner; parser_note=row_11 | AD12: =ROUND(ABS(H12)*8+ABS(I12)*1.5+ABS(J12)*3+ABS(K12)*2+ABS(L12)*2+ABS(M12)*2+ABS(N12)*2+ABS(O12)*2+IF(D12="Legendary",10,IF(D12="Relic",12,IF(D12="Epic",7,IF(D12="Rare",4,IF(D12="Uncommon",2,IF(D12="Cursed",5,1)))))),2) -> 3.58 | AE12: =MAX(0,ROUND(E12*(1+AD12/25)+IF(R12,2,0)+IF(T12,4,0),0)) -> 26 | AF12: =Q12-P12+1 -> 4 | AG12: =LEN(C12) -> 127 | AH12: =IF(D12="Legendary","boss-vault",IF(D12="Relic","secret-room",IF(D12="Cursed","curse-room",IF(AD12>12,"rare-chest","standard")))) -> standard | AI12: =OR(H12<0,I12<0,J12<0,K12<0,L12<0,M12<0,N12<0,O12<0) -> TRUE | AJ12: =IF(AND(P12<=Q12,AE12>=0,AF12>0),IF(OR(AD12>18,AND(D12="Common",AD12>10),AND(D12="Legendary",AE12<80)),"review: balance outlier",IF(AND(R12,T12,U12),"review: volatile physics",IF(COUNTIF(AA12,"*fire*")+COUNTIF(AA12,"*poison*")+COUNTIF(AA12,"*ice*")>=2,"review: multi-status synergy","ok"))),"invalid: level/price") -> ok | AK12: =not_a_formula_0011 | AM12: 46155 | AN12: =P12<=Q12 -> TRUE
A13: itm_00012 | B13: Hungry Rocket of Panic | C13: A legendary familiar that taxes reloads after every third hit. Generated test item #0012; element=Slime; pool=Secret. | D13: Legendary | E13: 102 | F13: TRUE | G13: 146 | H13: 0.99 | I13: 0 | J13: 0.1 | K13: 0 | L13: 0 | M13: 0 | N13: 0 | O13: 0 | P13: 3 | Q13: 7 | R13: FALSE | S13: FALSE | T13: TRUE | U13: FALSE | V13: FALSE | W13: Slime | X13: Familiar | Y13: Secret | Z13: 2.661 | AA13: slime,explosive,companion | AB13: scr_item_hungry_rocket_of_panic | AC13: seed=20260703; class_filter=Witch; parser_note=row_12 | AD13: =ROUND(ABS(H13)*8+ABS(I13)*1.5+ABS(J13)*3+ABS(K13)*2+ABS(L13)*2+ABS(M13)*2+ABS(N13)*2+ABS(O13)*2+IF(D13="Legendary",10,IF(D13="Relic",12,IF(D13="Epic",7,IF(D13="Rare",4,IF(D13="Uncommon",2,IF(D13="Cursed",5,1)))))),2) -> 18.22 | AE13: =MAX(0,ROUND(E13*(1+AD13/25)+IF(R13,2,0)+IF(T13,4,0),0)) -> 180 | AF13: =Q13-P13+1 -> 5 | AG13: =LEN(C13) -> 117 | AH13: =IF(D13="Legendary","boss-vault",IF(D13="Relic","secret-room",IF(D13="Cursed","curse-room",IF(AD13>12,"rare-chest","standard")))) -> boss-vault | AI13: =OR(H13<0,I13<0,J13<0,K13<0,L13<0,M13<0,N13<0,O13<0) -> FALSE | AJ13: =IF(AND(P13<=Q13,AE13>=0,AF13>0),IF(OR(AD13>18,AND(D13="Common",AD13>10),AND(D13="Legendary",AE13<80)),"review: balance outlier",IF(AND(R13,T13,U13),"review: volatile physics",IF(COUNTIF(AA13,"*fire*")+COUNTIF(AA13,"*poison*")+COUNTIF(AA13,"*ice*")>=2,"review: multi-status synergy","ok"))),"invalid: level/price") -> review: balance outlier | AK13: =not_a_formula_0012 | AM13: 46145 | AN13: =P13<=Q13 -> TRUE
A14: itm_00013 | B14: Lunar Onion of Tuesday | C14: A uncommon active that amplifies shops while lowering control. Generated test item #0013; element=Slime; pool=Shop. | D14: Uncommon | E14: 28 | F14: FALSE | G14: 987 | H14: -0.01 | I14: 0 | J14: 0 | K14: 0.61 | L14: 0 | M14: 0.37 | N14: 0 | O14: 0 | P14: 1 | Q14: 5 | R14: FALSE | S14: FALSE | T14: FALSE | U14: FALSE | V14: TRUE | W14: Slime | X14: Active | Y14: Shop | Z14: 0.361 | AA14: slime | AB14: scr_item_lunar_onion_of_tuesday | AC14: seed=20260703; class_filter=Witch; parser_note=row_13 | AD14: =ROUND(ABS(H14)*8+ABS(I14)*1.5+ABS(J14)*3+ABS(K14)*2+ABS(L14)*2+ABS(M14)*2+ABS(N14)*2+ABS(O14)*2+IF(D14="Legendary",10,IF(D14="Relic",12,IF(D14="Epic",7,IF(D14="Rare",4,IF(D14="Uncommon",2,IF(D14="Cursed",5,1)))))),2) -> 4.04 | AE14: =MAX(0,ROUND(E14*(1+AD14/25)+IF(R14,2,0)+IF(T14,4,0),0)) -> 33 | AF14: =Q14-P14+1 -> 5 | AG14: =LEN(C14) -> 115 | AH14: =IF(D14="Legendary","boss-vault",IF(D14="Relic","secret-room",IF(D14="Cursed","curse-room",IF(AD14>12,"rare-chest","standard")))) -> standard | AI14: =OR(H14<0,I14<0,J14<0,K14<0,L14<0,M14<0,N14<0,O14<0) -> TRUE | AJ14: =IF(AND(P14<=Q14,AE14>=0,AF14>0),IF(OR(AD14>18,AND(D14="Common",AD14>10),AND(D14="Legendary",AE14<80)),"review: balance outlier",IF(AND(R14,T14,U14),"review: volatile physics",IF(COUNTIF(AA14,"*fire*")+COUNTIF(AA14,"*poison*")+COUNTIF(AA14,"*ice*")>=2,"review: multi-status synergy","ok"))),"invalid: level/price") -> ok | AK14: =not_a_formula_0013 | AM14: 46098 | AN14: =P14<=Q14 -> TRUE
A15: itm_00014 | B15: Sour Boot of the Hungry Door | C15: A rare weaponmod that polishes dodges but attracts trouble. Generated test item #0014; element=Poison; pool=Shop. | D15: Rare | E15: 43 | F15: TRUE | G15: 83 | H15: 0 | I15: 1 | J15: 0.09 | K15: 0 | L15: 0 | M15: 0.08 | N15: 2.02 | O15: 0 | P15: 9 | Q15: 9 | R15: FALSE | S15: FALSE | T15: FALSE | U15: TRUE | V15: FALSE | W15: Poison | X15: WeaponMod | Y15: Shop | Z15: 1.9 | AA15: poison | AB15: scr_item_sour_boot_of_the_hungry_door | AC15: seed=20260703; class_filter=Monk; parser_note=row_14 | AD15: =ROUND(ABS(H15)*8+ABS(I15)*1.5+ABS(J15)*3+ABS(K15)*2+ABS(L15)*2+ABS(M15)*2+ABS(N15)*2+ABS(O15)*2+IF(D15="Legendary",10,IF(D15="Relic",12,IF(D15="Epic",7,IF(D15="Rare",4,IF(D15="Uncommon",2,IF(D15="Cursed",5,1)))))),2) -> 9.97 | AE15: =MAX(0,ROUND(E15*(1+AD15/25)+IF(R15,2,0)+IF(T15,4,0),0)) -> 60 | AF15: =Q15-P15+1 -> 1 | AG15: =LEN(C15) -> 113 | AH15: =IF(D15="Legendary","boss-vault",IF(D15="Relic","secret-room",IF(D15="Cursed","curse-room",IF(AD15>12,"rare-chest","standard")))) -> standard | AI15: =OR(H15<0,I15<0,J15<0,K15<0,L15<0,M15<0,N15<0,O15<0) -> FALSE | AJ15: =IF(AND(P15<=Q15,AE15>=0,AF15>0),IF(OR(AD15>18,AND(D15="Common",AD15>10),AND(D15="Legendary",AE15<80)),"review: balance outlier",IF(AND(R15,T15,U15),"review: volatile physics",IF(COUNTIF(AA15,"*fire*")+COUNTIF(AA15,"*poison*")+COUNTIF(AA15,"*ice*")>=2,"review: multi-status synergy","ok"))),"invalid: level/price") -> ok | AK15: =not_a_formula_0014 | AL15: upg_282 | AM15: 46047 | AN15: =P15<=Q15 -> TRUE
A16: itm_00015 | B16: Neon Key of Pocket Suns | C16: A uncommon weaponmod that warps reloads at a suspicious price. Generated test item #0015; element=Lightning; pool=Treasure. | D16: Uncommon | E16: 32 | F16: TRUE | G16: 1467 | H16: 0.27 | I16: -1 | J16: -0.04 | K16: 0 | L16: 0 | M16: 0 | N16: 0 | O16: 0 | P16: 8 | Q16: 10 | R16: FALSE | S16: FALSE | T16: TRUE | U16: FALSE | V16: FALSE | W16: Lightning | X16: WeaponMod | Y16: Treasure | Z16: 1.132 | AA16: lightning,explosive | AB16: scr_item_neon_key_of_pocket_suns | AC16: seed=20260703; class_filter=Any; parser_note=row_15 | AD16: =ROUND(ABS(H16)*8+ABS(I16)*1.5+ABS(J16)*3+ABS(K16)*2+ABS(L16)*2+ABS(M16)*2+ABS(N16)*2+ABS(O16)*2+IF(D16="Legendary",10,IF(D16="Relic",12,IF(D16="Epic",7,IF(D16="Rare",4,IF(D16="Uncommon",2,IF(D16="Cursed",5,1)))))),2) -> 5.78 | AE16: =MAX(0,ROUND(E16*(1+AD16/25)+IF(R16,2,0)+IF(T16,4,0),0)) -> 43 | AF16: =Q16-P16+1 -> 3 | AG16: =LEN(C16) -> 123 | AH16: =IF(D16="Legendary","boss-vault",IF(D16="Relic","secret-room",IF(D16="Cursed","curse-room",IF(AD16>12,"rare-chest","standard")))) -> standard | AI16: =OR(H16<0,I16<0,J16<0,K16<0,L16<0,M16<0,N16<0,O16<0) -> TRUE | AJ16: =IF(AND(P16<=Q16,AE16>=0,AF16>0),IF(OR(AD16>18,AND(D16="Common",AD16>10),AND(D16="Legendary",AE16<80)),"review: balance outlier",IF(AND(R16,T16,U16),"review: volatile physics",IF(COUNTIF(AA16,"*fire*")+COUNTIF(AA16,"*poison*")+COUNTIF(AA16,"*ice*")>=2,"review: multi-status synergy","ok"))),"invalid: level/price") -> ok | AK16: =not_a_formula_0015 | AM16: 46104 | AN16: =P16<=Q16 -> TRUE
A17: itm_00016 | B17: Spicy Feather of Ricochet | C17: A epic orbital that nudges hearts only when the room is clear. Generated test item #0016; element=Slime; pool=Treasure. | D17: Epic | E17: 89 | F17: FALSE | G17: 750 | H17: 1.12 | I17: 0 | J17: -0.21 | K17: 0 | L17: 0 | M17: 0.3 | N17: 0 | O17: 0 | P17: 4 | Q17: 7 | R17: FALSE | S17: FALSE | T17: FALSE | U17: TRUE | V17: FALSE | W17: Slime | X17: Orbital | Y17: Treasure | Z17: 3.145 | AA17: slime,companion | AB17: scr_item_spicy_feather_of_ricochet | AC17: seed=20260703; class_filter=Engineer; parser_note=row_16 | AD17: =ROUND(ABS(H17)*8+ABS(I17)*1.5+ABS(J17)*3+ABS(K17)*2+ABS(L17)*2+ABS(M17)*2+ABS(N17)*2+ABS(O17)*2+IF(D17="Legendary",10,IF(D17="Relic",12,IF(D17="Epic",7,IF(D17="Rare",4,IF(D17="Uncommon",2,IF(D17="Cursed",5,1)))))),2) -> 17.19 | AE17: =MAX(0,ROUND(E17*(1+AD17/25)+IF(R17,2,0)+IF(T17,4,0),0)) -> 150 | AF17: =Q17-P17+1 -> 4 | AG17: =LEN(C17) -> 119 | AH17: =IF(D17="Legendary","boss-vault",IF(D17="Relic","secret-room",IF(D17="Cursed","curse-room",IF(AD17>12,"rare-chest","standard")))) -> rare-chest | AI17: =OR(H17<0,I17<0,J17<0,K17<0,L17<0,M17<0,N17<0,O17<0) -> TRUE | AJ17: =IF(AND(P17<=Q17,AE17>=0,AF17>0),IF(OR(AD17>18,AND(D17="Common",AD17>10),AND(D17="Legendary",AE17<80)),"review: balance outlier",IF(AND(R17,T17,U17),"review: volatile physics",IF(COUNTIF(AA17,"*fire*")+COUNTIF(AA17,"*poison*")+COUNTIF(AA17,"*ice*")>=2,"review: multi-status synergy","ok"))),"invalid: level/price") -> ok | AK17: =not_a_formula_0016 | AM17: 46057 | AN17: =P17<=Q17 -> TRUE
A18: itm_00017 | B18: Caffeinated Capacitor of the Basement | C18: A common weaponmod that nudges keys near breakable props. Generated test item #0017; element=Slime; pool=Shop. | D18: Common | E18: 11 | F18: TRUE | G18: 978 | H18: 0 | I18: 0 | J18: 0 | K18: 0 | L18: 0 | M18: 0 | N18: 0 | O18: 0 | P18: 6 | Q18: 6 | R18: FALSE | S18: FALSE | T18: FALSE | U18: FALSE | V18: TRUE | W18: Slime | X18: WeaponMod | Y18: Shop | Z18: 1.941 | AA18: slime | AB18: scr_item_caffeinated_capacitor_of_the_basement | AC18: seed=20260703; class_filter=Engineer; parser_note=row_17 | AD18: =ROUND(ABS(H18)*8+ABS(I18)*1.5+ABS(J18)*3+ABS(K18)*2+ABS(L18)*2+ABS(M18)*2+ABS(N18)*2+ABS(O18)*2+IF(D18="Legendary",10,IF(D18="Relic",12,IF(D18="Epic",7,IF(D18="Rare",4,IF(D18="Uncommon",2,IF(D18="Cursed",5,1)))))),2) -> 1 | AE18: =MAX(0,ROUND(E18*(1+AD18/25)+IF(R18,2,0)+IF(T18,4,0),0)) -> 11 | AF18: =Q18-P18+1 -> 1 | AG18: =LEN(C18) -> 110 | AH18: =IF(D18="Legendary","boss-vault",IF(D18="Relic","secret-room",IF(D18="Cursed","curse-room",IF(AD18>12,"rare-chest","standard")))) -> standard | AI18: =OR(H18<0,I18<0,J18<0,K18<0,L18<0,M18<0,N18<0,O18<0) -> FALSE | AJ18: =IF(AND(P18<=Q18,AE18>=0,AF18>0),IF(OR(AD18>18,AND(D18="Common",AD18>10),AND(D18="Legendary",AE18<80)),"review: balance outlier",IF(AND(R18,T18,U18),"review: volatile physics",IF(COUNTIF(AA18,"*fire*")+COUNTIF(AA18,"*poison*")+COUNTIF(AA18,"*ice*")>=2,"review: multi-status synergy","ok"))),"invalid: level/price") -> ok | AK18: =not_a_formula_0017 | AL18: upg_015 | AM18: 46116 | AN18: =P18<=Q18 -> TRUE
A19: itm_00018 | B19: Haunted Pepper of Worms | C19: A uncommon passive that polishes bombs while lowering control. Generated test item #0018; element=Slime; pool=Treasure. | D19: Uncommon | E19: 37 | F19: TRUE | G19: 1196 | H19: 1.52 | I19: -1 | J19: 0 | K19: 0 | L19: 0 | M19: 0 | N19: 0 | O19: 0.35 | P19: 5 | Q19: 10 | R19: FALSE | S19: TRUE | T19: FALSE | U19: FALSE | V19: FALSE | W19: Slime | X19: Passive | Y19: Treasure | Z19: 2.186 | AA19: slime,poisonable | AB19: scr_item_haunted_pepper_of_worms | AC19: seed=20260703; class_filter=Witch; parser_note=row_18 | AD19: =ROUND(ABS(H19)*8+ABS(I19)*1.5+ABS(J19)*3+ABS(K19)*2+ABS(L19)*2+ABS(M19)*2+ABS(N19)*2+ABS(O19)*2+IF(D19="Legendary",10,IF(D19="Relic",12,IF(D19="Epic",7,IF(D19="Rare",4,IF(D19="Uncommon",2,IF(D19="Cursed",5,1)))))),2) -> 16.36 | AE19: =MAX(0,ROUND(E19*(1+AD19/25)+IF(R19,2,0)+IF(T19,4,0),0)) -> 61 | AF19: =Q19-P19+1 -> 6 | AG19: =LEN(C19) -> 119 | AH19: =IF(D19="Legendary","boss-vault",IF(D19="Relic","secret-room",IF(D19="Cursed","curse-room",IF(AD19>12,"rare-chest","standard")))) -> rare-chest | AI19: =OR(H19<0,I19<0,J19<0,K19<0,L19<0,M19<0,N19<0,O19<0) -> TRUE | AJ19: =IF(AND(P19<=Q19,AE19>=0,AF19>0),IF(OR(AD19>18,AND(D19="Common",AD19>10),AND(D19="Legendary",AE19<80)),"review: balance outlier",IF(AND(R19,T19,U19),"review: volatile physics",IF(COUNTIF(AA19,"*fire*")+COUNTIF(AA19,"*poison*")+COUNTIF(AA19,"*ice*")>=2,"review: multi-status synergy","ok"))),"invalid: level/price") -> ok | AK19: =not_a_formula_0018 | AM19: 46028 | AN19: =P19<=Q19 -> TRUE
A20: itm_00019 | B20: Lucky Donut of the Hungry Door | C20: A relic familiar that haunts bullets near breakable props. Generated test item #0019; element=None; pool=Shop. | D20: Relic | E20: 176 | F20: FALSE | G20: 1375 | H20: 1.41 | I20: 1 | J20: 0 | K20: 0 | L20: 0 | M20: 0 | N20: 0 | O20: 0 | P20: 8 | Q20: 9 | R20: FALSE | S20: FALSE | T20: FALSE | U20: TRUE | V20: TRUE | W20: None | X20: Familiar | Y20: Shop | Z20: 2.293 | AA20: companion,relic | AB20: scr_item_lucky_donut_of_the_hungry_door | AC20: seed=20260703; class_filter=Any; parser_note=row_19 | AD20: =ROUND(ABS(H20)*8+ABS(I20)*1.5+ABS(J20)*3+ABS(K20)*2+ABS(L20)*2+ABS(M20)*2+ABS(N20)*2+ABS(O20)*2+IF(D20="Legendary",10,IF(D20="Relic",12,IF(D20="Epic",7,IF(D20="Rare",4,IF(D20="Uncommon",2,IF(D20="Cursed",5,1)))))),2) -> 24.78 | AE20: =MAX(0,ROUND(E20*(1+AD20/25)+IF(R20,2,0)+IF(T20,4,0),0)) -> 350 | AF20: =Q20-P20+1 -> 2 | AG20: =LEN(C20) -> 110 | AH20: =IF(D20="Legendary","boss-vault",IF(D20="Relic","secret-room",IF(D20="Cursed","curse-room",IF(AD20>12,"rare-chest","standard")))) -> secret-room | AI20: =OR(H20<0,I20<0,J20<0,K20<0,L20<0,M20<0,N20<0,O20<0) -> FALSE | AJ20: =IF(AND(P20<=Q20,AE20>=0,AF20>0),IF(OR(AD20>18,AND(D20="Common",AD20>10),AND(D20="Legendary",AE20<80)),"review: balance outlier",IF(AND(R20,T20,U20),"review: volatile physics",IF(COUNTIF(AA20,"*fire*")+COUNTIF(AA20,"*poison*")+COUNTIF(AA20,"*ice*")>=2,"review: multi-status synergy","ok"))),"invalid: level/price") -> review: balance outlier | AK20: =not_a_formula_0019 | AL20: upg_180 | AM20: 46159 | AN20: =P20<=Q20 -> TRUE
A21: itm_00020 | B21: Cardboard Slingshot of the Basement | C21: A common orbital that haunts bullets near breakable props. Generated test item #0020; element=None; pool=Shop. | D21: Common | E21: 12 | F21: FALSE | G21: 357 | H21: 0 | I21: 0 | J21: 0.26 | K21: 0.47 | L21: 0 | M21: 0.36 | N21: 0 | O21: 0.13 | P21: 4 | Q21: 4 | R21: FALSE | S21: FALSE | T21: FALSE | U21: FALSE | V21: TRUE | W21: None | X21: Orbital | Y21: Shop | Z21: 2.989 | AA21: companion | AB21: scr_item_cardboard_slingshot_of_the_basement | AC21: seed=20260703; class_filter=Monk; parser_note=row_20 | AD21: =ROUND(ABS(H21)*8+ABS(I21)*1.5+ABS(J21)*3+ABS(K21)*2+ABS(L21)*2+ABS(M21)*2+ABS(N21)*2+ABS(O21)*2+IF(D21="Legendary",10,IF(D21="Relic",12,IF(D21="Epic",7,IF(D21="Rare",4,IF(D21="Uncommon",2,IF(D21="Cursed",5,1)))))),2) -> 3.7 | AE21: =MAX(0,ROUND(E21*(1+AD21/25)+IF(R21,2,0)+IF(T21,4,0),0)) -> 14 | AF21: =Q21-P21+1 -> 1 | AG21: =LEN(C21) -> 110 | AH21: =IF(D21="Legendary","boss-vault",IF(D21="Relic","secret-room",IF(D21="Cursed","curse-room",IF(AD21>12,"rare-chest","standard")))) -> standard | AI21: =OR(H21<0,I21<0,J21<0,K21<0,L21<0,M21<0,N21<0,O21<0) -> FALSE | AJ21: =IF(AND(P21<=Q21,AE21>=0,AF21>0),IF(OR(AD21>18,AND(D21="Common",AD21>10),AND(D21="Legendary",AE21<80)),"review: balance outlier",IF(AND(R21,T21,U21),"review: volatile physics",IF(COUNTIF(AA21,"*fire*")+COUNTIF(AA21,"*poison*")+COUNTIF(AA21,"*ice*")>=2,"review: multi-status synergy","ok"))),"invalid: level/price") -> ok | AK21: =not_a_formula_0020 | AM21: 46114 | AN21: =P21<=Q21 -> TRUE
A22: itm_00021 | B22: Radiant Candle of the Final Room | C22: A common relic that polishes bullets near breakable props. Generated test item #0021; element=Poison; pool=Shop. | D22: Common | E22: 11 | F22: TRUE | G22: 1199 | H22: 0 | I22: 1 | J22: 0 | K22: 0.61 | L22: 0 | M22: 0.02 | N22: 0 | O22: 0 | P22: 3 | Q22: 3 | R22: FALSE | S22: FALSE | T22: FALSE | U22: TRUE | V22: FALSE | W22: Poison | X22: Relic | Y22: Shop | Z22: 1.77 | AA22: poison | AB22: scr_item_radiant_candle_of_the_final_room | AC22: seed=20260703; class_filter=Gunner; parser_note=row_21 | AD22: =ROUND(ABS(H22)*8+ABS(I22)*1.5+ABS(J22)*3+ABS(K22)*2+ABS(L22)*2+ABS(M22)*2+ABS(N22)*2+ABS(O22)*2+IF(D22="Legendary",10,IF(D22="Relic",12,IF(D22="Epic",7,IF(D22="Rare",4,IF(D22="Uncommon",2,IF(D22="Cursed",5,1)))))),2) -> 3.76 | AE22: =MAX(0,ROUND(E22*(1+AD22/25)+IF(R22,2,0)+IF(T22,4,0),0)) -> 13 | AF22: =Q22-P22+1 -> 1 | AG22: =LEN(C22) -> 112 | AH22: =IF(D22="Legendary","boss-vault",IF(D22="Relic","secret-room",IF(D22="Cursed","curse-room",IF(AD22>12,"rare-chest","standard")))) -> standard | AI22: =OR(H22<0,I22<0,J22<0,K22<0,L22<0,M22<0,N22<0,O22<0) -> FALSE | AJ22: =IF(AND(P22<=Q22,AE22>=0,AF22>0),IF(OR(AD22>18,AND(D22="Common",AD22>10),AND(D22="Legendary",AE22<80)),"review: balance outlier",IF(AND(R22,T22,U22),"review: volatile physics",IF(COUNTIF(AA22,"*fire*")+COUNTIF(AA22,"*poison*")+COUNTIF(AA22,"*ice*")>=2,"review: multi-status synergy","ok"))),"invalid: level/price") -> ok | AK22: =not_a_formula_0021 | AM22: 46141 | AN22: =P22<=Q22 -> TRUE
A23: itm_00022 | B23: Recursive Skull of Ricochet | C23: A common charm that amplifies doors only when the room is clear. Generated test item #0022; element=Fire; pool=Challenge. | D23: Common | E23: 38 | F23: FALSE | G23: 1066 | H23: 0 | I23: 0 | J23: 0 | K23: 0 | L23: 0 | M23: 0 | N23: 1.75 | O23: 0 | P23: 2 | Q23: 10 | R23: TRUE | S23: FALSE | T23: TRUE | U23: FALSE | V23: TRUE | W23: Fire | X23: Charm | Y23: Challenge | Z23: 2.445 | AA23: fire,explosive | AB23: scr_item_recursive_skull_of_ricochet | AC23: seed=20260703; class_filter=Witch; parser_note=row_22 | AD23: =ROUND(ABS(H23)*8+ABS(I23)*1.5+ABS(J23)*3+ABS(K23)*2+ABS(L23)*2+ABS(M23)*2+ABS(N23)*2+ABS(O23)*2+IF(D23="Legendary",10,IF(D23="Relic",12,IF(D23="Epic",7,IF(D23="Rare",4,IF(D23="Uncommon",2,IF(D23="Cursed",5,1)))))),2) -> 4.5 | AE23: =MAX(0,ROUND(E23*(1+AD23/25)+IF(R23,2,0)+IF(T23,4,0),0)) -> 51 | AF23: =Q23-P23+1 -> 9 | AG23: =LEN(C23) -> 121 | AH23: =IF(D23="Legendary","boss-vault",IF(D23="Relic","secret-room",IF(D23="Cursed","curse-room",IF(AD23>12,"rare-chest","standard")))) -> standard | AI23: =OR(H23<0,I23<0,J23<0,K23<0,L23<0,M23<0,N23<0,O23<0) -> FALSE | AJ23: =IF(AND(P23<=Q23,AE23>=0,AF23>0),IF(OR(AD23>18,AND(D23="Common",AD23>10),AND(D23="Legendary",AE23<80)),"review: balance outlier",IF(AND(R23,T23,U23),"review: volatile physics",IF(COUNTIF(AA23,"*fire*")+COUNTIF(AA23,"*poison*")+COUNTIF(AA23,"*ice*")>=2,"review: multi-status synergy","ok"))),"invalid: level/price") -> ok | AK23: =not_a_formula_0022 | AM23: 46154 | AN23: =P23<=Q23 -> TRUE
A24: itm_00023 | B24: Echoing Whistle of Oversteer | C24: A uncommon charm that duplicates doors at a suspicious price. Generated test item #0023; element=Fire; pool=Treasure. | D24: Uncommon | E24: 28 | F24: TRUE | G24: 1905 | H24: 0 | I24: 1 | J24: -0.32 | K24: 0.57 | L24: 0 | M24: -0.1 | N24: 0 | O24: 0 | P24: 6 | Q24: 6 | R24: TRUE | S24: TRUE | T24: TRUE | U24: FALSE | V24: TRUE | W24: Fire | X24: Charm | Y24: Treasure | Z24: 2.599 | AA24: fire,explosive,poisonable | AB24: scr_item_echoing_whistle_of_oversteer | AC24: seed=20260703; class_filter=Rogue; parser_note=row_23 | AD24: =ROUND(ABS(H24)*8+ABS(I24)*1.5+ABS(J24)*3+ABS(K24)*2+ABS(L24)*2+ABS(M24)*2+ABS(N24)*2+ABS(O24)*2+IF(D24="Legendary",10,IF(D24="Relic",12,IF(D24="Epic",7,IF(D24="Rare",4,IF(D24="Uncommon",2,IF(D24="Cursed",5,1)))))),2) -> 5.8 | AE24: =MAX(0,ROUND(E24*(1+AD24/25)+IF(R24,2,0)+IF(T24,4,0),0)) -> 40 | AF24: =Q24-P24+1 -> 1 | AG24: =LEN(C24) -> 117 | AH24: =IF(D24="Legendary","boss-vault",IF(D24="Relic","secret-room",IF(D24="Cursed","curse-room",IF(AD24>12,"rare-chest","standard")))) -> standard | AI24: =OR(H24<0,I24<0,J24<0,K24<0,L24<0,M24<0,N24<0,O24<0) -> TRUE | AJ24: =IF(AND(P24<=Q24,AE24>=0,AF24>0),IF(OR(AD24>18,AND(D24="Common",AD24>10),AND(D24="Legendary",AE24<80)),"review: balance outlier",IF(AND(R24,T24,U24),"review: volatile physics",IF(COUNTIF(AA24,"*fire*")+COUNTIF(AA24,"*poison*")+COUNTIF(AA24,"*ice*")>=2,"review: multi-status synergy","ok"))),"invalid: level/price") -> review: multi-status synergy | AK24: =not_a_formula_0023 | AM24: 46053 | AN24: =P24<=Q24 -> TRUE
A25: itm_00024 | B25: Crooked Button of Double Trouble | C25: A uncommon passive that duplicates reloads near breakable props. Generated test item #0024; element=Slime; pool=Challenge. | D25: Uncommon | E25: 24 | F25: TRUE | G25: 388 | H25: 1.16 | I25: 0 | J25: 0 | K25: -0.16 | L25: 0.42 | M25: 0 | N25: 2.3 | O25: 0 | P25: 6 | Q25: 6 | R25: FALSE | S25: TRUE | T25: FALSE | U25: TRUE | V25: FALSE | W25: Slime | X25: Passive | Y25: Challenge | Z25: 3.432 | AA25: slime,poisonable | AB25: scr_item_crooked_button_of_double_trouble | AC25: seed=20260703; class_filter=Monk; parser_note=row_24 | AD25: =ROUND(ABS(H25)*8+ABS(I25)*1.5+ABS(J25)*3+ABS(K25)*2+ABS(L25)*2+ABS(M25)*2+ABS(N25)*2+ABS(O25)*2+IF(D25="Legendary",10,IF(D25="Relic",12,IF(D25="Epic",7,IF(D25="Rare",4,IF(D25="Uncommon",2,IF(D25="Cursed",5,1)))))),2) -> 17.04 | AE25: =MAX(0,ROUND(E25*(1+AD25/25)+IF(R25,2,0)+IF(T25,4,0),0)) -> 40 | AF25: =Q25-P25+1 -> 1 | AG25: =LEN(C25) -> 122 | AH25: =IF(D25="Legendary","boss-vault",IF(D25="Relic","secret-room",IF(D25="Cursed","curse-room",IF(AD25>12,"rare-chest","standard")))) -> rare-chest | AI25: =OR(H25<0,I25<0,J25<0,K25<0,L25<0,M25<0,N25<0,O25<0) -> TRUE | AJ25: =IF(AND(P25<=Q25,AE25>=0,AF25>0),IF(OR(AD25>18,AND(D25="Common",AD25>10),AND(D25="Legendary",AE25<80)),"review: balance outlier",IF(AND(R25,T25,U25),"review: volatile physics",IF(COUNTIF(AA25,"*fire*")+COUNTIF(AA25,"*poison*")+COUNTIF(AA25,"*ice*")>=2,"review: multi-status synergy","ok"))),"invalid: level/price") -> ok | AK25: =not_a_formula_0024 | AM25: 46086 | AN25: =P25<=Q25 -> TRUE
A26: itm_00025 | B26: Lucky Mask of the Hungry Door | C26: A epic familiar that nudges familiars when luck disagrees. Generated test item #0025; element=Ice; pool=Treasure. | D26: Epic | E26: 88 | F26: TRUE | G26: 556 | H26: 0 | I26: 1 | J26: 0.54 | K26: 0 | L26: 0 | M26: 0 | N26: 0 | O26: 0.65 | P26: 8 | Q26: 8 | R26: FALSE | S26: TRUE | T26: FALSE | U26: FALSE | V26: FALSE | W26: Ice | X26: Familiar | Y26: Treasure | Z26: 1.543 | AA26: ice,poisonable,companion | AB26: scr_item_lucky_mask_of_the_hungry_door | AC26: seed=20260703; class_filter=Rogue; parser_note=row_25 | AD26: =ROUND(ABS(H26)*8+ABS(I26)*1.5+ABS(J26)*3+ABS(K26)*2+ABS(L26)*2+ABS(M26)*2+ABS(N26)*2+ABS(O26)*2+IF(D26="Legendary",10,IF(D26="Relic",12,IF(D26="Epic",7,IF(D26="Rare",4,IF(D26="Uncommon",2,IF(D26="Cursed",5,1)))))),2) -> 11.42 | AE26: =MAX(0,ROUND(E26*(1+AD26/25)+IF(R26,2,0)+IF(T26,4,0),0)) -> 128 | AF26: =Q26-P26+1 -> 1 | AG26: =LEN(C26) -> 113 | AH26: =IF(D26="Legendary","boss-vault",IF(D26="Relic","secret-room",IF(D26="Cursed","curse-room",IF(AD26>12,"rare-chest","standard")))) -> standard | AI26: =OR(H26<0,I26<0,J26<0,K26<0,L26<0,M26<0,N26<0,O26<0) -> FALSE | AJ26: =IF(AND(P26<=Q26,AE26>=0,AF26>0),IF(OR(AD26>18,AND(D26="Common",AD26>10),AND(D26="Legendary",AE26<80)),"review: balance outlier",IF(AND(R26,T26,U26),"review: volatile physics",IF(COUNTIF(AA26,"*fire*")+COUNTIF(AA26,"*poison*")+COUNTIF(AA26,"*ice*")>=2,"review: multi-status synergy","ok"))),"invalid: level/price") -> review: multi-status synergy | AK26: =not_a_formula_0025 | AL26: upg_325 | AM26: 46044 | AN26: =P26<=Q26 -> TRUE
A27: itm_00026 | B27: Sour Badge of the Final Room | C27: A uncommon orbital that amplifies keys while lowering control. Generated test item #0026; element=Poison; pool=Treasure. | D27: Uncommon | E27: 27 | F27: TRUE | G27: 1102 | H27: 0.51 | I27: 0 | J27: -0.31 | K27: 0 | L27: 0 | M27: 0.08 | N27: 0 | O27: 1 | P27: 9 | Q27: 10 | R27: FALSE | S27: FALSE | T27: TRUE | U27: FALSE | V27: TRUE | W27: Poison | X27: Orbital | Y27: Treasure | Z27: 2.808 | AA27: poison,explosive,companion | AB27: scr_item_sour_badge_of_the_final_room | AC27: seed=20260703; class_filter=Monk; parser_note=row_26 | AD27: =ROUND(ABS(H27)*8+ABS(I27)*1.5+ABS(J27)*3+ABS(K27)*2+ABS(L27)*2+ABS(M27)*2+ABS(N27)*2+ABS(O27)*2+IF(D27="Legendary",10,IF(D27="Relic",12,IF(D27="Epic",7,IF(D27="Rare",4,IF(D27="Uncommon",2,IF(D27="Cursed",5,1)))))),2) -> 9.17 | AE27: =MAX(0,ROUND(E27*(1+AD27/25)+IF(R27,2,0)+IF(T27,4,0),0)) -> 41 | AF27: =Q27-P27+1 -> 2 | AG27: =LEN(C27) -> 120 | AH27: =IF(D27="Legendary","boss-vault",IF(D27="Relic","secret-room",IF(D27="Cursed","curse-room",IF(AD27>12,"rare-chest","standard")))) -> standard | AI27: =OR(H27<0,I27<0,J27<0,K27<0,L27<0,M27<0,N27<0,O27<0) -> TRUE | AJ27: =IF(AND(P27<=Q27,AE27>=0,AF27>0),IF(OR(AD27>18,AND(D27="Common",AD27>10),AND(D27="Legendary",AE27<80)),"review: balance outlier",IF(AND(R27,T27,U27),"review: volatile physics",IF(COUNTIF(AA27,"*fire*")+COUNTIF(AA27,"*poison*")+COUNTIF(AA27,"*ice*")>=2,"review: multi-status synergy","ok"))),"invalid: level/price") -> ok | AK27: =not_a_formula_0026 | AL27: upg_042 | AM27: 46105 | AN27: =P27<=Q27 -> TRUE
A28: itm_00027 | B28: Forgotten Rocket of Slippery Angles | C28: A epic passive that spoils reloads while lowering control. Generated test item #0027; element=Poison; pool=Shop. | D28: Epic | E28: 57 | F28: FALSE | G28: 1543 | H28: -0.24 | I28: 2 | J28: 0.18 | K28: 0.45 | L28: 0 | M28: 0 | N28: 2.63 | O28: 0.67 | P28: 6 | Q28: 6 | R28: FALSE | S28: FALSE | T28: FALSE | U28: FALSE | V28: TRUE | W28: Poison | X28: Passive | Y28: Shop | Z28: 3.256 | AA28: poison | AB28: scr_item_forgotten_rocket_of_slippery_angles | AC28: seed=20260703; class_filter=Witch; parser_note=row_27 | AD28: =ROUND(ABS(H28)*8+ABS(I28)*1.5+ABS(J28)*3+ABS(K28)*2+ABS(L28)*2+ABS(M28)*2+ABS(N28)*2+ABS(O28)*2+IF(D28="Legendary",10,IF(D28="Relic",12,IF(D28="Epic",7,IF(D28="Rare",4,IF(D28="Uncommon",2,IF(D28="Cursed",5,1)))))),2) -> 19.96 | AE28: =MAX(0,ROUND(E28*(1+AD28/25)+IF(R28,2,0)+IF(T28,4,0),0)) -> 103 | AF28: =Q28-P28+1 -> 1 | AG28: =LEN(C28) -> 112 | AH28: =IF(D28="Legendary","boss-vault",IF(D28="Relic","secret-room",IF(D28="Cursed","curse-room",IF(AD28>12,"rare-chest","standard")))) -> rare-chest | AI28: =OR(H28<0,I28<0,J28<0,K28<0,L28<0,M28<0,N28<0,O28<0) -> TRUE | AJ28: =IF(AND(P28<=Q28,AE28>=0,AF28>0),IF(OR(AD28>18,AND(D28="Common",AD28>10),AND(D28="Legendary",AE28<80)),"review: balance outlier",IF(AND(R28,T28,U28),"review: volatile physics",IF(COUNTIF(AA28,"*fire*")+COUNTIF(AA28,"*poison*")+COUNTIF(AA28,"*ice*")>=2,"review: multi-status synergy","ok"))),"invalid: level/price") -> review: balance outlier | AK28: =not_a_formula_0027 | AL28: upg_039 | AM28: 46128 | AN28: =P28<=Q28 -> TRUE
A29: itm_00028 | B29: Plastic Lunchbox of Last Chances | C29: A rare passive that nudges shops near breakable props. Generated test item #0028; element=Lightning; pool=Shop. | D29: Rare | E29: 34 | F29: TRUE | G29: 1111 | H29: 0.18 | I29: 0 | J29: 0 | K29: 0 | L29: 0 | M29: -0.12 | N29: -1.48 | O29: 0 | P29: 7 | Q29: 7 | R29: FALSE | S29: FALSE | T29: TRUE | U29: TRUE | V29: TRUE | W29: Lightning | X29: Passive | Y29: Shop | Z29: 2.891 | AA29: lightning,explosive | AB29: scr_item_plastic_lunchbox_of_last_chances | AC29: seed=20260703; class_filter=Brawler; parser_note=row_28 | AD29: =ROUND(ABS(H29)*8+ABS(I29)*1.5+ABS(J29)*3+ABS(K29)*2+ABS(L29)*2+ABS(M29)*2+ABS(N29)*2+ABS(O29)*2+IF(D29="Legendary",10,IF(D29="Relic",12,IF(D29="Epic",7,IF(D29="Rare",4,IF(D29="Uncommon",2,IF(D29="Cursed",5,1)))))),2) -> 8.64 | AE29: =MAX(0,ROUND(E29*(1+AD29/25)+IF(R29,2,0)+IF(T29,4,0),0)) -> 50 | AF29: =Q29-P29+1 -> 1 | AG29: =LEN(C29) -> 111 | AH29: =IF(D29="Legendary","boss-vault",IF(D29="Relic","secret-room",IF(D29="Cursed","curse-room",IF(AD29>12,"rare-chest","standard")))) -> standard | AI29: =OR(H29<0,I29<0,J29<0,K29<0,L29<0,M29<0,N29<0,O29<0) -> TRUE | AJ29: =IF(AND(P29<=Q29,AE29>=0,AF29>0),IF(OR(AD29>18,AND(D29="Common",AD29>10),AND(D29="Legendary",AE29<80)),"review: balance outlier",IF(AND(R29,T29,U29),"review: volatile physics",IF(COUNTIF(AA29,"*fire*")+COUNTIF(AA29,"*poison*")+COUNTIF(AA29,"*ice*")>=2,"review: multi-status synergy","ok"))),"invalid: level/price") -> ok | AK29: =not_a_formula_0028 | AM29: 46029 | AN29: =P29<=Q29 -> TRUE
A30: itm_00029 | B30: Tiny Mask of Oversteer | C30: A common active that haunts dodges at a suspicious price. Generated test item #0029; element=Ice; pool=Secret. | D30: Common | E30: 10 | F30: TRUE | G30: 34 | H30: 0 | I30: 0 | J30: 0.07 | K30: 0 | L30: 0.23 | M30: 0 | N30: 0 | O30: 0.09 | P30: 6 | Q30: 6 | R30: TRUE | S30: TRUE | T30: FALSE | U30: FALSE | V30: TRUE | W30: Ice | X30: Active | Y30: Secret | Z30: 0.681 | AA30: ice,poisonable | AB30: scr_item_tiny_mask_of_oversteer | AC30: seed=20260703; class_filter=Gunner; parser_note=row_29 | AD30: =ROUND(ABS(H30)*8+ABS(I30)*1.5+ABS(J30)*3+ABS(K30)*2+ABS(L30)*2+ABS(M30)*2+ABS(N30)*2+ABS(O30)*2+IF(D30="Legendary",10,IF(D30="Relic",12,IF(D30="Epic",7,IF(D30="Rare",4,IF(D30="Uncommon",2,IF(D30="Cursed",5,1)))))),2) -> 1.85 | AE30: =MAX(0,ROUND(E30*(1+AD30/25)+IF(R30,2,0)+IF(T30,4,0),0)) -> 13 | AF30: =Q30-P30+1 -> 1 | AG30: =LEN(C30) -> 110 | AH30: =IF(D30="Legendary","boss-vault",IF(D30="Relic","secret-room",IF(D30="Cursed","curse-room",IF(AD30>12,"rare-chest","standard")))) -> standard | AI30: =OR(H30<0,I30<0,J30<0,K30<0,L30<0,M30<0,N30<0,O30<0) -> FALSE | AJ30: =IF(AND(P30<=Q30,AE30>=0,AF30>0),IF(OR(AD30>18,AND(D30="Common",AD30>10),AND(D30="Legendary",AE30<80)),"review: balance outlier",IF(AND(R30,T30,U30),"review: volatile physics",IF(COUNTIF(AA30,"*fire*")+COUNTIF(AA30,"*poison*")+COUNTIF(AA30,"*ice*")>=2,"review: multi-status synergy","ok"))),"invalid: level/price") -> review: multi-status synergy | AK30: =not_a_formula_0029 | AM30: 46104 | AN30: =P30<=Q30 -> TRUE
A31: itm_00030 | B31: Hollow Magnet of Worms | C31: A uncommon consumable that polishes doors near breakable props. Generated test item #0030; element=Fire; pool=Treasure. | D31: Uncommon | E31: 38 | F31: TRUE | G31: 1942 | H31: 0 | I31: 0 | J31: 0 | K31: 0 | L31: 0 | M31: 0 | N31: 0.85 | O31: 0 | P31: 5 | Q31: 10 | R31: TRUE | S31: TRUE | T31: TRUE | U31: FALSE | V31: FALSE | W31: Fire | X31: Consumable | Y31: Treasure | Z31: 3.341 | AA31: fire,explosive,poisonable | AB31: scr_item_hollow_magnet_of_worms | AC31: seed=20260703; class_filter=Alchemist; parser_note=row_30 | AD31: =ROUND(ABS(H31)*8+ABS(I31)*1.5+ABS(J31)*3+ABS(K31)*2+ABS(L31)*2+ABS(M31)*2+ABS(N31)*2+ABS(O31)*2+IF(D31="Legendary",10,IF(D31="Relic",12,IF(D31="Epic",7,IF(D31="Rare",4,IF(D31="Uncommon",2,IF(D31="Cursed",5,1)))))),2) -> 3.7 | AE31: =MAX(0,ROUND(E31*(1+AD31/25)+IF(R31,2,0)+IF(T31,4,0),0)) -> 50 | AF31: =Q31-P31+1 -> 6 | AG31: =LEN(C31) -> 119 | AH31: =IF(D31="Legendary","boss-vault",IF(D31="Relic","secret-room",IF(D31="Cursed","curse-room",IF(AD31>12,"rare-chest","standard")))) -> standard | AI31: =OR(H31<0,I31<0,J31<0,K31<0,L31<0,M31<0,N31<0,O31<0) -> FALSE | AJ31: =IF(AND(P31<=Q31,AE31>=0,AF31>0),IF(OR(AD31>18,AND(D31="Common",AD31>10),AND(D31="Legendary",AE31<80)),"review: balance outlier",IF(AND(R31,T31,U31),"review: volatile physics",IF(COUNTIF(AA31,"*fire*")+COUNTIF(AA31,"*poison*")+COUNTIF(AA31,"*ice*")>=2,"review: multi-status synergy","ok"))),"invalid: level/price") -> review: multi-status synergy | AK31: =not_a_formula_0030 | AM31: 46169 | AN31: =P31<=Q31 -> TRUE
A32: itm_00031 | B32: Mossy Fishbone of the Hungry Door | C32: A rare relic that haunts hearts if the player keeps moving. Generated test item #0031; element=Slime; pool=Arcade. | D32: Rare | E32: 54 | F32: FALSE | G32: 1270 | H32: 0 | I32: 1 | J32: 0 | K32: 0 | L32: -0.07 | M32: -0.2 | N32: 2.12 | O32: 0 | P32: 1 | Q32: 5 | R32: FALSE | S32: TRUE | T32: FALSE | U32: FALSE | V32: FALSE | W32: Slime | X32: Relic | Y32: Arcade | Z32: 0.839 | AA32: slime,poisonable | AB32: scr_item_mossy_fishbone_of_the_hungry_door | AC32: seed=20260703; class_filter=Monk; parser_note=row_31 | AD32: =ROUND(ABS(H32)*8+ABS(I32)*1.5+ABS(J32)*3+ABS(K32)*2+ABS(L32)*2+ABS(M32)*2+ABS(N32)*2+ABS(O32)*2+IF(D32="Legendary",10,IF(D32="Relic",12,IF(D32="Epic",7,IF(D32="Rare",4,IF(D32="Uncommon",2,IF(D32="Cursed",5,1)))))),2) -> 10.28 | AE32: =MAX(0,ROUND(E32*(1+AD32/25)+IF(R32,2,0)+IF(T32,4,0),0)) -> 76 | AF32: =Q32-P32+1 -> 5 | AG32: =LEN(C32) -> 114 | AH32: =IF(D32="Legendary","boss-vault",IF(D32="Relic","secret-room",IF(D32="Cursed","curse-room",IF(AD32>12,"rare-chest","standard")))) -> standard | AI32: =OR(H32<0,I32<0,J32<0,K32<0,L32<0,M32<0,N32<0,O32<0) -> TRUE | AJ32: =IF(AND(P32<=Q32,AE32>=0,AF32>0),IF(OR(AD32>18,AND(D32="Common",AD32>10),AND(D32="Legendary",AE32<80)),"review: balance outlier",IF(AND(R32,T32,U32),"review: volatile physics",IF(COUNTIF(AA32,"*fire*")+COUNTIF(AA32,"*poison*")+COUNTIF(AA32,"*ice*")>=2,"review: multi-status synergy","ok"))),"invalid: level/price") -> ok | AK32: =not_a_formula_0031 | AM32: 46162 | AN32: =P32<=Q32 -> TRUE
A33: itm_00032 | B33: Damp Kite of Friendly Fire | C33: A uncommon orbital that haunts bombs if the player keeps moving. Generated test item #0032; element=Lightning; pool=Shop. | D33: Uncommon | E33: 17 | F33: TRUE | G33: 403 | H33: 0 | I33: 0 | J33: -0.15 | K33: -0.25 | L33: 0 | M33: 0 | N33: 0 | O33: 0 | P33: 9 | Q33: 9 | R33: FALSE | S33: TRUE | T33: TRUE | U33: FALSE | V33: TRUE | W33: Lightning | X33: Orbital | Y33: Shop | Z33: 2.187 | AA33: lightning,explosive,poisonable,companion | AB33: scr_item_damp_kite_of_friendly_fire | AC33: seed=20260703; class_filter=Brawler; parser_note=row_32 | AD33: =ROUND(ABS(H33)*8+ABS(I33)*1.5+ABS(J33)*3+ABS(K33)*2+ABS(L33)*2+ABS(M33)*2+ABS(N33)*2+ABS(O33)*2+IF(D33="Legendary",10,IF(D33="Relic",12,IF(D33="Epic",7,IF(D33="Rare",4,IF(D33="Uncommon",2,IF(D33="Cursed",5,1)))))),2) -> 2.95 | AE33: =MAX(0,ROUND(E33*(1+AD33/25)+IF(R33,2,0)+IF(T33,4,0),0)) -> 23 | AF33: =Q33-P33+1 -> 1 | AG33: =LEN(C33) -> 121 | AH33: =IF(D33="Legendary","boss-vault",IF(D33="Relic","secret-room",IF(D33="Cursed","curse-room",IF(AD33>12,"rare-chest","standard")))) -> standard | AI33: =OR(H33<0,I33<0,J33<0,K33<0,L33<0,M33<0,N33<0,O33<0) -> TRUE | AJ33: =IF(AND(P33<=Q33,AE33>=0,AF33>0),IF(OR(AD33>18,AND(D33="Common",AD33>10),AND(D33="Legendary",AE33<80)),"review: balance outlier",IF(AND(R33,T33,U33),"review: volatile physics",IF(COUNTIF(AA33,"*fire*")+COUNTIF(AA33,"*poison*")+COUNTIF(AA33,"*ice*")>=2,"review: multi-status synergy","ok"))),"invalid: level/price") -> ok | AK33: =not_a_formula_0032 | AM33: 46172 | AN33: =P33<=Q33 -> TRUE
A34: itm_00033 | B34: Forgotten Magnet of Worms | C34: A common weaponmod that haunts bombs near breakable props. Generated test item #0033; element=Fire; pool=Library. | D34: Common | E34: 24 | F34: TRUE | G34: 1564 | H34: 0 | I34: -1 | J34: 0 | K34: 0 | L34: -0.15 | M34: 0.17 | N34: 0 | O34: 0 | P34: 4 | Q34: 8 | R34: TRUE | S34: TRUE | T34: TRUE | U34: FALSE | V34: FALSE | W34: Fire | X34: WeaponMod | Y34: Library | Z34: 3.361 | AA34: fire,explosive,poisonable | AB34: scr_item_forgotten_magnet_of_worms | AC34: seed=20260703; class_filter=Any; parser_note=row_33 | AD34: =ROUND(ABS(H34)*8+ABS(I34)*1.5+ABS(J34)*3+ABS(K34)*2+ABS(L34)*2+ABS(M34)*2+ABS(N34)*2+ABS(O34)*2+IF(D34="Legendary",10,IF(D34="Relic",12,IF(D34="Epic",7,IF(D34="Rare",4,IF(D34="Uncommon",2,IF(D34="Cursed",5,1)))))),2) -> 3.14 | AE34: =MAX(0,ROUND(E34*(1+AD34/25)+IF(R34,2,0)+IF(T34,4,0),0)) -> 33 | AF34: =Q34-P34+1 -> 5 | AG34: =LEN(C34) -> 113 | AH34: =IF(D34="Legendary","boss-vault",IF(D34="Relic","secret-room",IF(D34="Cursed","curse-room",IF(AD34>12,"rare-chest","standard")))) -> standard | AI34: =OR(H34<0,I34<0,J34<0,K34<0,L34<0,M34<0,N34<0,O34<0) -> TRUE | AJ34: =IF(AND(P34<=Q34,AE34>=0,AF34>0),IF(OR(AD34>18,AND(D34="Common",AD34>10),AND(D34="Legendary",AE34<80)),"review: balance outlier",IF(AND(R34,T34,U34),"review: volatile physics",IF(COUNTIF(AA34,"*fire*")+COUNTIF(AA34,"*poison*")+COUNTIF(AA34,"*ice*")>=2,"review: multi-status synergy","ok"))),"invalid: level/price") -> review: multi-status synergy | AK34: =not_a_formula_0033 | AL34: upg_335 | AM34: 46080 | AN34: =P34<=Q34 -> TRUE
A35: itm_00034 | B35: Haunted Marble of the Hungry Door | C35: A uncommon relic that shrinks bombs if the player keeps moving. Generated test item #0034; element=Holy; pool=Treasure. | D35: Uncommon | E35: 39 | F35: TRUE | G35: 811 | H35: 0 | I35: 0 | J35: 0 | K35: 0 | L35: 0 | M35: -0.01 | N35: 0 | O35: 0 | P35: 6 | Q35: 10 | R35: FALSE | S35: TRUE | T35: FALSE | U35: FALSE | V35: FALSE | W35: Holy | X35: Relic | Y35: Treasure | Z35: 3.169 | AA35: holy,poisonable | AB35: scr_item_haunted_marble_of_the_hungry_door | AC35: seed=20260703; class_filter=Brawler; parser_note=row_34 | AD35: =ROUND(ABS(H35)*8+ABS(I35)*1.5+ABS(J35)*3+ABS(K35)*2+ABS(L35)*2+ABS(M35)*2+ABS(N35)*2+ABS(O35)*2+IF(D35="Legendary",10,IF(D35="Relic",12,IF(D35="Epic",7,IF(D35="Rare",4,IF(D35="Uncommon",2,IF(D35="Cursed",5,1)))))),2) -> 2.02 | AE35: =MAX(0,ROUND(E35*(1+AD35/25)+IF(R35,2,0)+IF(T35,4,0),0)) -> 42 | AF35: =Q35-P35+1 -> 5 | AG35: =LEN(C35) -> 119 | AH35: =IF(D35="Legendary","boss-vault",IF(D35="Relic","secret-room",IF(D35="Cursed","curse-room",IF(AD35>12,"rare-chest","standard")))) -> standard | AI35: =OR(H35<0,I35<0,J35<0,K35<0,L35<0,M35<0,N35<0,O35<0) -> TRUE | AJ35: =IF(AND(P35<=Q35,AE35>=0,AF35>0),IF(OR(AD35>18,AND(D35="Common",AD35>10),AND(D35="Legendary",AE35<80)),"review: balance outlier",IF(AND(R35,T35,U35),"review: volatile physics",IF(COUNTIF(AA35,"*fire*")+COUNTIF(AA35,"*poison*")+COUNTIF(AA35,"*ice*")>=2,"review: multi-status synergy","ok"))),"invalid: level/price") -> ok | AK35: =not_a_formula_0034 | AL35: upg_257 | AM35: 46060 | AN35: =P35<=Q35 -> TRUE
A36: itm_00035 | B36: Hollow Candle of the Glass Moon | C36: A common active that spoils bombs only when the room is clear. Generated test item #0035; element=Holy; pool=Treasure. | D36: Common | E36: 18 | F36: TRUE | G36: 1365 | H36: 0 | I36: 1 | J36: 0 | K36: -0.18 | L36: 0 | M36: 0 | N36: 0 | O36: 0 | P36: 1 | Q36: 3 | R36: FALSE | S36: FALSE | T36: FALSE | U36: TRUE | V36: TRUE | W36: Holy | X36: Active | Y36: Treasure | Z36: 2.885 | AA36: holy | AB36: scr_item_hollow_candle_of_the_glass_moon | AC36: seed=20260703; class_filter=Brawler; parser_note=row_35 | AD36: =ROUND(ABS(H36)*8+ABS(I36)*1.5+ABS(J36)*3+ABS(K36)*2+ABS(L36)*2+ABS(M36)*2+ABS(N36)*2+ABS(O36)*2+IF(D36="Legendary",10,IF(D36="Relic",12,IF(D36="Epic",7,IF(D36="Rare",4,IF(D36="Uncommon",2,IF(D36="Cursed",5,1)))))),2) -> 2.86 | AE36: =MAX(0,ROUND(E36*(1+AD36/25)+IF(R36,2,0)+IF(T36,4,0),0)) -> 20 | AF36: =Q36-P36+1 -> 3 | AG36: =LEN(C36) -> 118 | AH36: =IF(D36="Legendary","boss-vault",IF(D36="Relic","secret-room",IF(D36="Cursed","curse-room",IF(AD36>12,"rare-chest","standard")))) -> standard | AI36: =OR(H36<0,I36<0,J36<0,K36<0,L36<0,M36<0,N36<0,O36<0) -> TRUE | AJ36: =IF(AND(P36<=Q36,AE36>=0,AF36>0),IF(OR(AD36>18,AND(D36="Common",AD36>10),AND(D36="Legendary",AE36<80)),"review: balance outlier",IF(AND(R36,T36,U36),"review: volatile physics",IF(COUNTIF(AA36,"*fire*")+COUNTIF(AA36,"*poison*")+COUNTIF(AA36,"*ice*")>=2,"review: multi-status synergy","ok"))),"invalid: level/price") -> ok | AK36: =not_a_formula_0035 | AM36: 46135 | AN36: =P36<=Q36 -> TRUE
A37: itm_00036 | B37: Crooked Lantern of Slippery Angles | C37: A rare relic that taxes dodges at a suspicious price. Generated test item #0036; element=Fire; pool=Secret. | D37: Rare | E37: 60 | F37: FALSE | G37: 1917 | H37: 1.41 | I37: 0 | J37: 0 | K37: 0 | L37: 0 | M37: 0 | N37: 0 | O37: 0.55 | P37: 3 | Q37: 5 | R37: FALSE | S37: FALSE | T37: TRUE | U37: FALSE | V37: FALSE | W37: Fire | X37: Relic | Y37: Secret | Z37: 2.207 | AA37: fire,explosive | AB37: scr_item_crooked_lantern_of_slippery_angles | AC37: seed=20260703; class_filter=Rogue; parser_note=row_36 | AD37: =ROUND(ABS(H37)*8+ABS(I37)*1.5+ABS(J37)*3+ABS(K37)*2+ABS(L37)*2+ABS(M37)*2+ABS(N37)*2+ABS(O37)*2+IF(D37="Legendary",10,IF(D37="Relic",12,IF(D37="Epic",7,IF(D37="Rare",4,IF(D37="Uncommon",2,IF(D37="Cursed",5,1)))))),2) -> 16.38 | AE37: =MAX(0,ROUND(E37*(1+AD37/25)+IF(R37,2,0)+IF(T37,4,0),0)) -> 103 | AF37: =Q37-P37+1 -> 3 | AG37: =LEN(C37) -> 107 | AH37: =IF(D37="Legendary","boss-vault",IF(D37="Relic","secret-room",IF(D37="Cursed","curse-room",IF(AD37>12,"rare-chest","standard")))) -> rare-chest | AI37: =OR(H37<0,I37<0,J37<0,K37<0,L37<0,M37<0,N37<0,O37<0) -> FALSE | AJ37: =IF(AND(P37<=Q37,AE37>=0,AF37>0),IF(OR(AD37>18,AND(D37="Common",AD37>10),AND(D37="Legendary",AE37<80)),"review: balance outlier",IF(AND(R37,T37,U37),"review: volatile physics",IF(COUNTIF(AA37,"*fire*")+COUNTIF(AA37,"*poison*")+COUNTIF(AA37,"*ice*")>=2,"review: multi-status synergy","ok"))),"invalid: level/price") -> ok | AK37: =not_a_formula_0036 | AM37: 46131 | AN37: =P37<=Q37 -> TRUE
A38: itm_00037 | B38: Bitter Marble of Bad Ideas | C38: A common relic that warps reloads but attracts trouble. Generated test item #0037; element=None; pool=Treasure. | D38: Common | E38: 19 | F38: FALSE | G38: 1346 | H38: 0 | I38: 0 | J38: -0.22 | K38: 0 | L38: 0 | M38: 0.21 | N38: 0 | O38: 0 | P38: 3 | Q38: 5 | R38: FALSE | S38: TRUE | T38: FALSE | U38: FALSE | V38: FALSE | W38: None | X38: Relic | Y38: Treasure | Z38: 1.123 | AA38: poisonable | AB38: scr_item_bitter_marble_of_bad_ideas | AC38: seed=20260703; class_filter=Monk; parser_note=row_37 | AD38: =ROUND(ABS(H38)*8+ABS(I38)*1.5+ABS(J38)*3+ABS(K38)*2+ABS(L38)*2+ABS(M38)*2+ABS(N38)*2+ABS(O38)*2+IF(D38="Legendary",10,IF(D38="Relic",12,IF(D38="Epic",7,IF(D38="Rare",4,IF(D38="Uncommon",2,IF(D38="Cursed",5,1)))))),2) -> 2.08 | AE38: =MAX(0,ROUND(E38*(1+AD38/25)+IF(R38,2,0)+IF(T38,4,0),0)) -> 21 | AF38: =Q38-P38+1 -> 3 | AG38: =LEN(C38) -> 111 | AH38: =IF(D38="Legendary","boss-vault",IF(D38="Relic","secret-room",IF(D38="Cursed","curse-room",IF(AD38>12,"rare-chest","standard")))) -> standard | AI38: =OR(H38<0,I38<0,J38<0,K38<0,L38<0,M38<0,N38<0,O38<0) -> TRUE | AJ38: =IF(AND(P38<=Q38,AE38>=0,AF38>0),IF(OR(AD38>18,AND(D38="Common",AD38>10),AND(D38="Legendary",AE38<80)),"review: balance outlier",IF(AND(R38,T38,U38),"review: volatile physics",IF(COUNTIF(AA38,"*fire*")+COUNTIF(AA38,"*poison*")+COUNTIF(AA38,"*ice*")>=2,"review: multi-status synergy","ok"))),"invalid: level/price") -> ok | AK38: =not_a_formula_0037 | AM38: 46124 | AN38: =P38<=Q38 -> TRUE
